<?xml version="1.0"?>
<robot
  name="solo">
  <link
    name="base_link">
    <inertial>
      <origin
        xyz="-0.180519447575436 0.00187198776323094 0.181381766624049"
        rpy="0 0 0" />
      <mass
        value="51.3841528437006" />
      <inertia
        ixx="3.81718679834589"
        ixy="0.0496729532697476"
        ixz="-0.508390617998127"
        iyy="5.59589156103865"
        iyz="-0.0198793511210422"
        izz="4.66966276048357" />
    </inertial>
    <visual>
      <origin
        xyz="0 0 0"
        rpy="0 0 0" />
      <geometry>
        <mesh
          filename="package://robot_description/meshes/base_link.STL" />
      </geometry>
      <material
        name="">
        <color
          rgba="0.96078431372549 0.96078431372549 0.964705882352941 1" />
      </material>
    </visual>
    <collision>
      <origin
        xyz="0 0 0"
        rpy="0 0 0" />
      <geometry>
        <mesh
          filename="package://robot_description/meshes/base_link.STL" />
      </geometry>
    </collision>
  </link>
  <link
    name="left_wheel">
    <inertial>
      <origin
        xyz="2.59694699078494E-09 7.61839784842178E-06 -0.0489938925473666"
        rpy="0 0 0" />
      <mass
        value="6.6345647962633" />
      <inertia
        ixx="0.07897998576173"
        ixy="8.22403524650973E-09"
        ixz="8.56621126378392E-10"
        iyy="0.0789799867511056"
        iyz="2.50152982395949E-06"
        izz="0.152212504564237" />
    </inertial>
    <visual>
      <origin
        xyz="0 0 0"
        rpy="0 0 0" />
      <geometry>
        <mesh
          filename="package://robot_description/meshes/left_wheel.STL" />
      </geometry>
      <material
        name="">
        <color
          rgba="0.627450980392157 0.627450980392157 0.627450980392157 1" />
      </material>
    </visual>
    <collision>
      <origin
        xyz="0 0 0"
        rpy="0 0 0" />
      <geometry>
        <mesh
          filename="package://robot_description/meshes/left_wheel.STL" />
      </geometry>
    </collision>
  </link>
  <joint
    name="base_link_to_left_wheel"
    type="continuous">
    <origin
      xyz="0 0.278 0"
      rpy="1.5708 0 0" />
    <parent
      link="base_link" />
    <child
      link="left_wheel" />
    <axis
      xyz="0 0 -1" />
  </joint>
  <link
    name="right_wheel">
    <inertial>
      <origin
        xyz="-5.28093547780273E-08 -7.61866608244011E-06 0.0492619903302725"
        rpy="0 0 0" />
      <mass
        value="6.63456472584469" />
      <inertia
        ixx="0.0789795305433076"
        ixy="8.14460439901073E-09"
        ixz="-1.74563458537794E-08"
        iyy="0.07897953111728"
        iyz="-2.51453323816836E-06"
        izz="0.152212504091262" />
    </inertial>
    <visual>
      <origin
        xyz="0 0 0"
        rpy="0 0 0" />
      <geometry>
        <mesh
          filename="package://robot_description/meshes/right_wheel.STL" />
      </geometry>
      <material
        name="">
        <color
          rgba="0.627450980392157 0.627450980392157 0.627450980392157 1" />
      </material>
    </visual>
    <collision>
      <origin
        xyz="0 0 0"
        rpy="0 0 0" />
      <geometry>
        <mesh
          filename="package://robot_description/meshes/right_wheel.STL" />
      </geometry>
    </collision>
  </link>
  <joint
    name="base_link_to_right_wheel"
    type="continuous">
    <origin
      xyz="0 -0.278 0"
      rpy="-1.5708 0 3.1416" />
    <parent
      link="base_link" />
    <child
      link="right_wheel" />
    <axis
      xyz="0 0 -1" />
  </joint>
  <link
    name="caster_part">
    <inertial>
      <origin
        xyz="0.0005556 0.092016 0.0043716"
        rpy="0 0 0" />
      <mass
        value="0.80166" />
      <inertia
        ixx="0.001908"
        ixy="-3.2888E-06"
        ixz="3.0127E-08"
        iyy="0.0015124"
        iyz="-0.00044014"
        izz="0.0015613" />
    </inertial>
    <visual>
      <origin
        xyz="0 0 0"
        rpy="0 0 0" />
      <geometry>
        <mesh
          filename="package://robot_description/meshes/caster_part.STL" />
      </geometry>
      <material
        name="">
        <color
          rgba="0.62745 0.62745 0.62745 1" />
      </material>
    </visual>
    <collision>
      <origin
        xyz="0 0 0"
        rpy="0 0 0" />
      <geometry>
        <mesh
          filename="package://robot_description/meshes/caster_part.STL" />
      </geometry>
    </collision>
  </link>
  <joint
    name="base_link_to_caster_part"
    type="continuous">
    <origin
      xyz="-0.696 -0.002 0.045"
      rpy="-1.5708 4.9021E-14 1.9615" />
    <parent
      link="base_link" />
    <child
      link="caster_part" />
    <axis
      xyz="0 -1 0" />
  </joint>
  
  <link
    name="caster_wheel">
    <inertial>
      <origin
        xyz="-5.107E-07 8.3995E-08 9.5441E-07"
        rpy="0 0 0" />
      <mass
        value="1.6238" />
      <inertia
        ixx="0.003191"
        ixy="-4.3713E-08"
        ixz="-1.6588E-08"
        iyy="0.0031917"
        iyz="4.1605E-09"
        izz="0.0051702" />
    </inertial>
    <visual>
      <origin
        xyz="0 0 0"
        rpy="0 0 0" />
      <geometry>
        <mesh
          filename="package://robot_description/meshes/caster_wheel.STL" />
      </geometry>
      <material
        name="">
        <color
          rgba="0.79216 0.81961 0.93333 1" />
      </material>
    </visual>
    <collision>
      <origin
        xyz="0 0 0"
        rpy="0 0 0" />
      <geometry>
        <mesh
          filename="package://robot_description/meshes/caster_wheel.STL" />
      </geometry>
    </collision>
  </link>
  <joint
    name="caster_wheel_to_caster_part"
    type="continuous">
    <origin
      xyz="0.0005 0.14403 0.053033"
      rpy="1.5708 1.2539 -1.5708" />
    <parent
      link="caster_part" />
    <child
      link="caster_wheel" />
    <axis
      xyz="0 0 1" />
  </joint>
  <link
    name="zed2i">
    <inertial>
      <origin
        xyz="0.0525000000000005 0.0497465331697187 0.0151477976012486"
        rpy="0 0 0" />
      <mass
        value="0.22167490681561" />
      <inertia
        ixx="0.00016343801956135"
        ixy="-1.07843176053233E-18"
        ixz="-4.20390247899892E-20"
        iyy="0.000165336577087661"
        iyz="-6.19672147423513E-08"
        izz="0.000235849488600523" />
    </inertial>
    <visual>
      <origin
        xyz="0 0 0"
        rpy="0 0 0" />
      <geometry>
        <mesh
          filename="package://robot_description/meshes/zed2i.STL" />
      </geometry>
      <material
        name="">
        <color
          rgba="0.792156862745098 0.819607843137255 0.933333333333333 1" />
      </material>
    </visual>
    <collision>
      <origin
        xyz="0 0 0"
        rpy="0 0 0" />
      <geometry>
        <mesh
          filename="package://robot_description/meshes/zed2i.STL" />
      </geometry>
    </collision>
  </link>
  <joint
    name="base_link_to_zed2i"
    type="fixed">
    <origin
      xyz="0.043 -0.057194 1.2351"
      rpy="1.5708 -0.003917 1.5708" />
    <parent
      link="base_link" />
    <child
      link="zed2i" />
    <axis
      xyz="0 0 0" />
  </joint>
  <link
    name="zed2i_cam">
    <inertial>
      <origin
        xyz="0.00314056704758986 5.25003776541411E-05 0.0160142317618688"
        rpy="0 0 0" />
      <mass
        value="0.726801281977045" />
      <inertia
        ixx="0.000167642379404196"
        ixy="3.90829276125947E-13"
        ixz="6.71902781368629E-14"
        iyy="0.00212571121934448"
        iyz="1.35162805187916E-07"
        izz="0.00216911264088625" />
    </inertial>
    <visual>
      <origin
        xyz="0 0 0"
        rpy="0 0 0" />
      <geometry>
        <mesh
          filename="package://robot_description/meshes/zed_cam.STL" />
      </geometry>
      <material
        name="">
        <color
          rgba="0.792156862745098 0.819607843137255 0.933333333333333 1" />
      </material>
    </visual>
    <collision>
      <origin
        xyz="0 0 0"
        rpy="0 0 0" />
      <geometry>
        <mesh
          filename="package://robot_description/meshes/zed_cam.STL" />
      </geometry>
    </collision>
  </link>
  <joint
    name="zed2i_to_zed_cam"
    type="fixed">
    <origin
      xyz="0.049359 0.093702 -0.00044896"
      rpy="0.010887 -7.5752E-17 1.4069E-15" />
    <parent
      link="zed2i" />
    <child
      link="zed2i_cam" />
    <axis
      xyz="0 0 0" />
  </joint>
  <link
    name="zed_slot">
    <inertial>
      <origin
        xyz="0.0525 0.022410175834066 0.0134463330565265"
        rpy="0 0 0" />
      <mass
        value="0.247827196256176" />
      <inertia
        ixx="9.37210893499663E-05"
        ixy="-1.64133809354202E-18"
        ixz="1.12592516258268E-19"
        iyy="0.000718038712621709"
        iyz="-2.53684820463082E-06"
        izz="0.000768774168537528" />
    </inertial>
    <visual>
      <origin
        xyz="0 0 0"
        rpy="0 0 0" />
      <geometry>
        <mesh
          filename="package://robot_description/meshes/zed_slot.STL" />
      </geometry>
      <material
        name="">
        <color
          rgba="0.792156862745098 0.819607843137255 0.933333333333333 1" />
      </material>
    </visual>
    <collision>
      <origin
        xyz="0 0 0"
        rpy="0 0 0" />
      <geometry>
        <mesh
          filename="package://robot_description/meshes/zed_slot.STL" />
      </geometry>
    </collision>
  </link>
  <joint
    name="base_link_to_zed_slot"
    type="fixed">
    <origin
      xyz="0.069 0.049588 0.78042"
      rpy="1.5708 0.003917 -1.5708" />
    <parent
      link="base_link" />
    <child
      link="zed_slot" />
    <axis
      xyz="0 1 0" />
  </joint>
</robot>